2025-04-11 16:03:28,640 - ERROR - The error ocurred in the funtion 'get_choise_1_to_5', in the module '__main__'
Traceback (most recent call last):
  File "/home/renepro/Renecito/Python/Avanced/.venv/lib/python3.12/site-packages/mysql/connector/connection_cext.py", line 755, in cmd_query
    self._cmysql.query(
_mysql_connector.MySQLInterfaceError: Duplicate entry 'poencima22@gmail.com' for key 'customers.email'

The above exception was the direct cause of the following exception:

Traceback (most recent call last):
  File "/home/renepro/Renecito/Python/Avanced/tools/sqlite3/package_poo/GetConnection.py", line 42, in connection
    yield connex
  File "/home/renepro/Renecito/Python/Avanced/tools/sqlite3/package_poo/Querys.py", line 63, in execute_query
    cursor.execute(query, row_data)
  File "/home/renepro/Renecito/Python/Avanced/.venv/lib/python3.12/site-packages/mysql/connector/cursor_cext.py", line 351, in execute
    self._connection.cmd_query(
  File "/home/renepro/Renecito/Python/Avanced/.venv/lib/python3.12/site-packages/mysql/connector/opentelemetry/context_propagation.py", line 97, in wrapper
    return method(cnx, *args, **kwargs)
           ^^^^^^^^^^^^^^^^^^^^^^^^^^^^
  File "/home/renepro/Renecito/Python/Avanced/.venv/lib/python3.12/site-packages/mysql/connector/connection_cext.py", line 763, in cmd_query
    raise get_mysql_exception(
mysql.connector.errors.IntegrityError: 1062 (23000): Duplicate entry 'poencima22@gmail.com' for key 'customers.email'

The above exception was the direct cause of the following exception:

Traceback (most recent call last):
  File "/home/renepro/Renecito/Python/Avanced/tools/sqlite3/t_logging.py", line 25, in wrapper
    result = fun(*args,**kwargs)
             ^^^^^^^^^^^^^^^^^^^
  File "/home/renepro/Renecito/Python/Avanced/tools/sqlite3/main.py", line 185, in get_choise_1_to_5
    raise ex
  File "/home/renepro/Renecito/Python/Avanced/tools/sqlite3/main.py", line 160, in get_choise_1_to_5
    insert.execute_query(conex.connection(), data_user)#call the method of the class 'InsertQuery'
    ^^^^^^^^^^^^^^^^^^^^^^^^^^^^^^^^^^^^^^^^^^^^^^^^^^^
  File "/home/renepro/Renecito/Python/Avanced/tools/sqlite3/package_poo/Querys.py", line 69, in execute_query
    raise  e# Re-lanza otras excepciones no esperadas
    ^^^^^^^^
  File "/home/renepro/Renecito/Python/Avanced/tools/sqlite3/package_poo/Querys.py", line 59, in execute_query
    with conection as conex:
  File "/usr/lib/python3.12/contextlib.py", line 158, in __exit__
    self.gen.throw(value)
  File "/home/renepro/Renecito/Python/Avanced/tools/sqlite3/package_poo/GetConnection.py", line 46, in connection
    raise type(e)(error_mesg) from e
mysql.connector.errors.IntegrityError: Error creating connection pool: 1062 (23000): Duplicate entry 'poencima22@gmail.com' for key 'customers.email'
